<?xml version="1.0" encoding="UTF-8"?>
<testng-results skipped="0" failed="1" total="2" passed="1">
  <reporter-output>
  </reporter-output>
  <suite name="Default suite" duration-ms="66605" started-at="2017-12-14T07:53:01Z" finished-at="2017-12-14T07:54:08Z">
    <groups>
    </groups>
    <test name="Default test" duration-ms="66605" started-at="2017-12-14T07:53:01Z" finished-at="2017-12-14T07:54:08Z">
      <class name="testCases.CreateNewAccount">
        <test-method status="PASS" signature="setUp()[pri:0, instance:testCases.CreateNewAccount@14acaea5]" name="setUp" is-config="true" duration-ms="32420" started-at="2017-12-14T13:23:01Z" finished-at="2017-12-14T13:23:33Z">
          <reporter-output>
          </reporter-output>
        </test-method> <!-- setUp -->
        <test-method status="FAIL" signature="faileTest()[pri:0, instance:testCases.CreateNewAccount@14acaea5]" name="faileTest" duration-ms="20" started-at="2017-12-14T13:23:33Z" finished-at="2017-12-14T13:23:33Z">
          <exception class="java.lang.AssertionError">
            <message>
              <![CDATA[expected [b] but found [a]]]>
            </message>
            <full-stacktrace>
              <![CDATA[java.lang.AssertionError: expected [b] but found [a]
	at org.testng.Assert.fail(Assert.java:94)
	at org.testng.Assert.failNotEquals(Assert.java:494)
	at org.testng.Assert.assertEquals(Assert.java:123)
	at org.testng.Assert.assertEquals(Assert.java:176)
	at org.testng.Assert.assertEquals(Assert.java:186)
	at testCases.CreateNewAccount.faileTest(CreateNewAccount.java:74)
	at sun.reflect.NativeMethodAccessorImpl.invoke0(Native Method)
	at sun.reflect.NativeMethodAccessorImpl.invoke(NativeMethodAccessorImpl.java:62)
	at sun.reflect.DelegatingMethodAccessorImpl.invoke(DelegatingMethodAccessorImpl.java:43)
	at java.lang.reflect.Method.invoke(Method.java:498)
	at org.testng.internal.MethodInvocationHelper.invokeMethod(MethodInvocationHelper.java:80)
	at org.testng.internal.Invoker.invokeMethod(Invoker.java:714)
	at org.testng.internal.Invoker.invokeTestMethod(Invoker.java:901)
	at org.testng.internal.Invoker.invokeTestMethods(Invoker.java:1231)
	at org.testng.internal.TestMethodWorker.invokeTestMethods(TestMethodWorker.java:127)
	at org.testng.internal.TestMethodWorker.run(TestMethodWorker.java:111)
	at org.testng.TestRunner.privateRun(TestRunner.java:767)
	at org.testng.TestRunner.run(TestRunner.java:617)
	at org.testng.SuiteRunner.runTest(SuiteRunner.java:334)
	at org.testng.SuiteRunner.runSequentially(SuiteRunner.java:329)
	at org.testng.SuiteRunner.privateRun(SuiteRunner.java:291)
	at org.testng.SuiteRunner.run(SuiteRunner.java:240)
	at org.testng.SuiteRunnerWorker.runSuite(SuiteRunnerWorker.java:52)
	at org.testng.SuiteRunnerWorker.run(SuiteRunnerWorker.java:86)
	at org.testng.TestNG.runSuitesSequentially(TestNG.java:1198)
	at org.testng.TestNG.runSuitesLocally(TestNG.java:1123)
	at org.testng.TestNG.run(TestNG.java:1031)
	at org.testng.remote.AbstractRemoteTestNG.run(AbstractRemoteTestNG.java:114)
	at org.testng.remote.RemoteTestNG.initAndRun(RemoteTestNG.java:251)
	at org.testng.remote.RemoteTestNG.main(RemoteTestNG.java:77)
]]>
            </full-stacktrace>
          </exception> <!-- java.lang.AssertionError -->
          <reporter-output>
          </reporter-output>
        </test-method> <!-- faileTest -->
        <test-method status="PASS" signature="tearDown(org.testng.ITestResult)[pri:0, instance:testCases.CreateNewAccount@14acaea5]" name="tearDown" is-config="true" duration-ms="1090" started-at="2017-12-14T13:23:33Z" finished-at="2017-12-14T13:23:35Z">
          <params>
            <param index="0">
              <value>
                <![CDATA[[TestResult name=faileTest status=FAILURE method=CreateNewAccount.faileTest()[pri:0, instance:testCases.CreateNewAccount@14acaea5] output={null}]]]>
              </value>
            </param>
          </params>
          <reporter-output>
          </reporter-output>
        </test-method> <!-- tearDown -->
        <test-method status="PASS" signature="setUp()[pri:0, instance:testCases.CreateNewAccount@14acaea5]" name="setUp" is-config="true" duration-ms="12524" started-at="2017-12-14T13:23:35Z" finished-at="2017-12-14T13:23:47Z">
          <reporter-output>
          </reporter-output>
        </test-method> <!-- setUp -->
        <test-method status="PASS" signature="verifyLoginCredentials()[pri:0, instance:testCases.CreateNewAccount@14acaea5]" name="verifyLoginCredentials" duration-ms="20163" started-at="2017-12-14T13:23:47Z" finished-at="2017-12-14T13:24:07Z">
          <reporter-output>
          </reporter-output>
        </test-method> <!-- verifyLoginCredentials -->
        <test-method status="FAIL" signature="tearDown(org.testng.ITestResult)[pri:0, instance:testCases.CreateNewAccount@14acaea5]" name="tearDown" is-config="true" duration-ms="0" started-at="2017-12-14T13:24:07Z" finished-at="2017-12-14T13:24:07Z">
          <params>
            <param index="0">
              <value>
                <![CDATA[[TestResult name=verifyLoginCredentials status=SUCCESS method=CreateNewAccount.verifyLoginCredentials()[pri:0, instance:testCases.CreateNewAccount@14acaea5] output={null}]]]>
              </value>
            </param>
          </params>
          <exception class="java.lang.NullPointerException">
            <full-stacktrace>
              <![CDATA[java.lang.NullPointerException
	at java.util.regex.Matcher.getTextLength(Matcher.java:1283)
	at java.util.regex.Matcher.reset(Matcher.java:309)
	at java.util.regex.Matcher.<init>(Matcher.java:229)
	at java.util.regex.Pattern.matcher(Pattern.java:1093)
	at com.aventstack.extentreports.utils.ExceptionUtil.getExceptionHeadline(ExceptionUtil.java:25)
	at com.aventstack.extentreports.ExtentTest.log(ExtentTest.java:399)
	at com.aventstack.extentreports.ExtentTest.log(ExtentTest.java:418)
	at testCases.CreateNewAccount.tearDown(CreateNewAccount.java:93)
	at sun.reflect.NativeMethodAccessorImpl.invoke0(Native Method)
	at sun.reflect.NativeMethodAccessorImpl.invoke(NativeMethodAccessorImpl.java:62)
	at sun.reflect.DelegatingMethodAccessorImpl.invoke(DelegatingMethodAccessorImpl.java:43)
	at java.lang.reflect.Method.invoke(Method.java:498)
	at org.testng.internal.MethodInvocationHelper.invokeMethod(MethodInvocationHelper.java:80)
	at org.testng.internal.Invoker.invokeConfigurationMethod(Invoker.java:564)
	at org.testng.internal.Invoker.invokeConfigurations(Invoker.java:213)
	at org.testng.internal.Invoker.invokeMethod(Invoker.java:786)
	at org.testng.internal.Invoker.invokeTestMethod(Invoker.java:901)
	at org.testng.internal.Invoker.invokeTestMethods(Invoker.java:1231)
	at org.testng.internal.TestMethodWorker.invokeTestMethods(TestMethodWorker.java:127)
	at org.testng.internal.TestMethodWorker.run(TestMethodWorker.java:111)
	at org.testng.TestRunner.privateRun(TestRunner.java:767)
	at org.testng.TestRunner.run(TestRunner.java:617)
	at org.testng.SuiteRunner.runTest(SuiteRunner.java:334)
	at org.testng.SuiteRunner.runSequentially(SuiteRunner.java:329)
	at org.testng.SuiteRunner.privateRun(SuiteRunner.java:291)
	at org.testng.SuiteRunner.run(SuiteRunner.java:240)
	at org.testng.SuiteRunnerWorker.runSuite(SuiteRunnerWorker.java:52)
	at org.testng.SuiteRunnerWorker.run(SuiteRunnerWorker.java:86)
	at org.testng.TestNG.runSuitesSequentially(TestNG.java:1198)
	at org.testng.TestNG.runSuitesLocally(TestNG.java:1123)
	at org.testng.TestNG.run(TestNG.java:1031)
	at org.testng.remote.AbstractRemoteTestNG.run(AbstractRemoteTestNG.java:114)
	at org.testng.remote.RemoteTestNG.initAndRun(RemoteTestNG.java:251)
	at org.testng.remote.RemoteTestNG.main(RemoteTestNG.java:77)
]]>
            </full-stacktrace>
          </exception> <!-- java.lang.NullPointerException -->
          <reporter-output>
          </reporter-output>
        </test-method> <!-- tearDown -->
      </class> <!-- testCases.CreateNewAccount -->
    </test> <!-- Default test -->
  </suite> <!-- Default suite -->
</testng-results>
